# LANGUAGE message translation file for plpython
# Copyright (C) 2009 PostgreSQL Global Development Group
# This file is distributed under the same license as the PostgreSQL package.
#
msgid ""
msgstr ""
"Project-Id-Version: PostgreSQL 9.0alpha4\n"
"Report-Msgid-Bugs-To: pgsql-bugs@postgresql.org\n"
"POT-Creation-Date: 2010-04-10 21:53+0900\n"
"PO-Revision-Date: 2010-04-10 10:31+0900\n"
"Last-Translator: HOTTA Michihide <hotta@net-newbie.com>\n"
"Language-Team: Japan PostgreSQL Users Group <jpug-doc@ml.postgresql.jp>\n"
"MIME-Version: 1.0\n"
"Content-Type: text/plain; charset=UTF-8\n"
"Content-Transfer-Encoding: 8bit\n"
"Plural-Forms: nplurals=2; plural=(n > 1);\n"

#: plpython.c:417
#, c-format
msgid "PL/Python function \"%s\""
msgstr "PL/Python 関数 \"%s\""

#: plpython.c:423
msgid "PL/Python anonymous code block"
msgstr "PL/Python の無名コードブロック"

#: plpython.c:430
msgid "while modifying trigger row"
msgstr "トリガー行の変更中に"

#: plpython.c:437
msgid "while creating return value"
msgstr "戻り値の作成中に"

#: plpython.c:603 plpython.c:629
msgid "unexpected return value from trigger procedure"
msgstr "トリガー手続きから期待しない戻り値が返されました"

#: plpython.c:604
msgid "Expected None or a string."
msgstr "None もしくは文字列を期待していました。"

#: plpython.c:619
msgid ""
"PL/Python trigger function returned \"MODIFY\" in a DELETE trigger -- ignored"
msgstr ""
"PL/Python トリガー関数が、DELETE トリガーで \"MODIFY\" を返しました-- 無視し"
"ました"

#: plpython.c:630
msgid "Expected None, \"OK\", \"SKIP\", or \"MODIFY\"."
msgstr "None, \"OK\", \"SKIP\", \"MODIFY\" のいずれかを期待していました"

#: plpython.c:682
msgid "TD[\"new\"] deleted, cannot modify row"
msgstr "TD[\"new\"] は削除されました。今となっては変更できません。"

#: plpython.c:685
msgid "TD[\"new\"] is not a dictionary"
msgstr "TD[\"new\"] は辞書ではありません"

#: plpython.c:709
#, c-format
msgid "TD[\"new\"] dictionary key at ordinal position %d is not a string"
msgstr "%d 番目の TD[\"new\"] 属性の名前が文字列ではありません"

#: plpython.c:715
#, c-format
msgid ""
"key \"%s\" found in TD[\"new\"] does not exist as a column in the triggering "
"row"
msgstr ""
"TD[\"new\"] で見つかったキー \"%s\" は、行レベルトリガーにおけるカラムとして"
"は存在しません"

#: plpython.c:808
msgid "could not create new dictionary while building trigger arguments"
msgstr "トリガーの引数を構成中に、新しい辞書を生成できませんでした"

#: plpython.c:1015
msgid "unsupported set function return mode"
msgstr "未サポートの集合関数リターンモードです"

#: plpython.c:1016
msgid ""
"PL/Python set-returning functions only support returning only value per call."
msgstr ""
"PL/Python の集合を返す関数では、コールのたびに値だけを返すことしかできません"

#: plpython.c:1028
msgid "returned object cannot be iterated"
msgstr "返されたオブジェクトは反復適用できません"

#: plpython.c:1029
msgid "PL/Python set-returning functions must return an iterable object."
msgstr ""
"PL/Python の集合を返す関数では、反復可能オブジェクトを返さなければなりません"

#: plpython.c:1056
msgid "error fetching next item from iterator"
msgstr "イテレータ（反復子）から次の項目をフェッチ（取り出し）できません"

#: plpython.c:1078
msgid "PL/Python function with return type \"void\" did not return None"
msgstr "\"void\" 型を返す PL/Python 関数は None 型を返しません"

#: plpython.c:1235
msgid "PyList_SetItem() failed, while setting up arguments"
msgstr "引数を設定する際に、PyList_SetItem() に失敗しました"

#: plpython.c:1239
msgid "PyDict_SetItemString() failed, while setting up arguments"
msgstr "引数を設定する際に、PyDict_SetItemString() に失敗しました"

#: plpython.c:1414
msgid "trigger functions can only be called as triggers"
msgstr "トリガー関数はトリガーとしてのみコールできます"

#: plpython.c:1418 plpython.c:1799
#, c-format
msgid "PL/Python functions cannot return type %s"
msgstr "PL/Python 関数は %s 型を返せません"

#: plpython.c:1496
#, c-format
msgid "PL/Python functions cannot accept type %s"
msgstr "PL/Python 関数は %s 型を受け付けません"

#: plpython.c:1590
#, c-format
msgid "could not compile PL/Python function \"%s\""
msgstr "PL/Python 関数 \"%s\" をコンパイルできませんでした"

#: plpython.c:1801
msgid "PL/Python does not support conversion to arrays of row types."
msgstr "PL/Python は行タイプが配列の場合の変換をサポートしていません"

#: plpython.c:1994
msgid "cannot convert multidimensional array to Python list"
msgstr "多次元配列を Python のリストに変換できません"

#: plpython.c:1995
msgid "PL/Python only supports one-dimensional arrays."
msgstr "PL/Python は一次元配列だけをサポートしています"

#: plpython.c:2029
msgid "could not create new dictionary"
msgstr "新しいディレクトリを作れませんでした"

#: plpython.c:2105
msgid "could not create bytes representation of Python object"
msgstr "Python オブジェクトのバイト表現を生成できませんでした"

#: plpython.c:2160
msgid "could not create string representation of Python object"
msgstr "Python オブジェクトの文字列表現を生成できませんでした"

#: plpython.c:2171
msgid ""
"could not convert Python object into cstring: Python string representation "
"appears to contain null bytes"
msgstr ""
"Python オブジェクトを ctring に変換できませんでした：Python の文字列表現に "
"null バイトが含まれているようです"

#: plpython.c:2203
msgid ""
"return value of function with array return type is not a Python sequence"
msgstr "配列の戻り値を持つ関数の戻り値は Python のシーケンスではありません"

#: plpython.c:2275
#, c-format
msgid "key \"%s\" not found in mapping"
msgstr "マッピング上にキー \"%s\" が見つかりません"

#: plpython.c:2276
msgid ""
"To return null in a column, add the value None to the mapping with the key "
"named after the column."
msgstr ""
"カラムに null を入れて返すには、そのカラムの後につけた名前をキーとしてマッピ"
"ングに None 値を追加してください"

#: plpython.c:2319
msgid "length of returned sequence did not match number of columns in row"
msgstr "返されたシーケンスの長さが、その行のカラム数と異なります"

#: plpython.c:2412
#, c-format
msgid "attribute \"%s\" does not exist in Python object"
msgstr "属性 \"%s\" が Python オブジェクト中に存在しません"

#: plpython.c:2413
msgid ""
"To return null in a column, let the returned object have an attribute named "
"after column with value None."
msgstr ""
"カラムに null を入れて返す場合は、そのカラムの後につけた名前で表される属性が"
"値として None を持ち、返されるオブジェクトがその属性を含むようにしてください"

#: plpython.c:2647
msgid "plan.status takes no arguments"
msgstr "plan.status は引数を取りません"

#: plpython.c:2771 plpython.c:2913
msgid "transaction aborted"
msgstr "トランザクションがアボートしました"

#: plpython.c:2778
msgid "invalid arguments for plpy.prepare"
msgstr "plpy.prepare の引数が不正です"

#: plpython.c:2785
msgid "second argument of plpy.prepare must be a sequence"
msgstr "plpy.prepare の第二引数はシーケンスでなければなりません"

#: plpython.c:2835
#, c-format
msgid "plpy.prepare: type name at ordinal position %d is not a string"
msgstr "plpy.prepare: %d 番目の型名が文字列ではありません"

#: plpython.c:2862
msgid "plpy.prepare does not support composite types"
msgstr "plpy.prepare は複合型をサポートしていません"

#: plpython.c:2890
msgid "unrecognized error in PLy_spi_prepare"
msgstr "PLy_spi_prepare で認識できないエラーを検出しました"

#: plpython.c:2926
msgid "plpy.execute expected a query or a plan"
msgstr "plpy.execute はクエリーもしくは実行計画を期待していました"

#: plpython.c:2943
msgid "plpy.execute takes a sequence as its second argument"
msgstr "plpy.execute は第二引数としてシーケンスを取ります"

#: plpython.c:2959 plpython.c:2990
msgid "could not execute plan"
msgstr "プランを実行できませんでした"

#: plpython.c:2962
#, c-format
msgid "Expected sequence of %d argument, got %d: %s"
msgid_plural "Expected sequence of %d arguments, got %d: %s"
msgstr[0] "%d 番目の引数はシーケンスを期待していましたが、%d が現れました：%s"

#: plpython.c:3053
msgid "unrecognized error in PLy_spi_execute_plan"
msgstr "PLy_spi_execute_plan で認識できないエラーを検出しました"

#: plpython.c:3072
#, c-format
msgid "SPI_execute_plan failed: %s"
msgstr "SPI_execute_plan が失敗しました：%s"

#: plpython.c:3098
msgid "unrecognized error in PLy_spi_execute_query"
msgstr "PLy_spi_execute_query で認識できないエラーを検出しました"

#: plpython.c:3107
#, c-format
msgid "SPI_execute failed: %s"
msgstr "SPI_execute が失敗しました：%s"

#: plpython.c:3167
msgid "unrecognized error in PLy_spi_execute_fetch_result"
msgstr "PLy_spi_execute_fetch_result で認識できないエラーを検出しました"

#: plpython.c:3218
msgid "untrapped error in initialization"
msgstr "初期化中に捕獲できないエラーがありました"

#: plpython.c:3221
msgid "could not create procedure cache"
msgstr "手続き用キャッシュ(procedure cache)を生成できませんでした"

#: plpython.c:3233
msgid "could not import \"__main__\" module"
msgstr "\"__main__\" モジュールをインポートできませんでした"

#: plpython.c:3240
msgid "could not initialize globals"
msgstr "グローバル変数(globals)を初期化できませんでした"

#: plpython.c:3355
msgid "could not parse error message in plpy.elog"
msgstr "plpy.elog でエラーメッセージをパースできませんでした"

#: plpython.c:3480 plpython.c:3484
#, c-format
msgid "PL/Python: %s"
msgstr "PL/Python: %s"

#: plpython.c:3481
#, c-format
msgid "%s"
msgstr "%s"

#: plpython.c:3594
msgid "out of memory"
msgstr "メモリ不足です"

#: plpython.c:3665
msgid "could not convert Python Unicode object to PostgreSQL server encoding"
msgstr ""
"Python のユニコードオブジェクトを PostgreSQL サーバーのエンコーディングに変換"
"できませんでした"

#~ msgid "PL/Python function \"%s\" failed"
#~ msgstr "PL/Python 関数 \"%s\" が実行に失敗しました"
