# LANGUAGE message translation file for plpython
# Copyright (C) 2010 PostgreSQL Global Development Group
# This file is distributed under the same license as the PostgreSQL package.
# FIRST AUTHOR <EMAIL@ADDRESS>, 2010.
#
msgid ""
msgstr ""
"Project-Id-Version: PostgreSQL 8.4\n"
"Report-Msgid-Bugs-To: pgsql-bugs@postgresql.org\n"
"POT-Creation-Date: 2010-02-19 01:51+0000\n"
"PO-Revision-Date: 2010-03-30 14:49+0800\n"
"Last-Translator: Weibin <ssmei_2000@yahoo.com>\n"
"Language-Team: LANGUAGE <LL@li.org>\n"
"MIME-Version: 1.0\n"
"Content-Type: text/plain; charset=UTF-8\n"
"Content-Transfer-Encoding: 8bit\n"
"Plural-Forms: nplurals=1; plural=0;\n"

#: plpython.c:428
#: plpython.c:453
msgid "unexpected return value from trigger procedure"
msgstr "在触发器存储过程出现非期望的返回值"

#: plpython.c:429
msgid "Expected None or a string."
msgstr "期望空值或一个字符串"

#: plpython.c:443
msgid "PL/Python trigger function returned \"MODIFY\" in a DELETE trigger -- ignored"
msgstr "在DELETE触发器中的PL/Python 触发器函数返回 \"MODIFY\"  -- 忽略"

#: plpython.c:454
msgid "Expected None, \"OK\", \"SKIP\", or \"MODIFY\"."
msgstr "期望None, \"OK\", \"SKIP\", 或\"MODIFY\""

#: plpython.c:501
msgid "TD[\"new\"] deleted, cannot modify row"
msgstr "TD[\"new\"] 已删除，无法修改记录"

#: plpython.c:504
msgid "TD[\"new\"] is not a dictionary"
msgstr "TD[\"new\"]不是一个字典"

#: plpython.c:523
#, c-format
msgid "name of TD[\"new\"] attribute at ordinal position %d is not a string"
msgstr "在顺序位置%d的TD[\"new\"]属性名称不是字符串"

#: plpython.c:527
#, c-format
msgid "key \"%s\" found in TD[\"new\"] does not exist as a column in the triggering row"
msgstr "在 TD[\"new\"]中找到的键 \"%s\"在正在触发的记录中不是作为列而存在."

#: plpython.c:548
#, c-format
msgid "could not compute string representation of Python object in PL/Python function \"%s\" while modifying trigger row"
msgstr "在修改触发器记录的同时无法计算在PL/Python函数\"%s\"中Python对象的字符串表达式"

#: plpython.c:630
msgid "could not create new dictionary while building trigger arguments"
msgstr "在构建触发器参数的同时无法创建新的字典."

#: plpython.c:838
msgid "unsupported set function return mode"
msgstr "不支持集合函数返回模式"

#: plpython.c:839
msgid "PL/Python set-returning functions only support returning only value per call."
msgstr "PL/Python集合返回函数只支持在每次调用时返回值."

#: plpython.c:851
msgid "returned object cannot be iterated"
msgstr "所返回的对象无法迭代"

#: plpython.c:852
msgid "PL/Python set-returning functions must return an iterable object."
msgstr "PL/Python集合返回函数必须返回一个可迭代的对象."

#: plpython.c:880
msgid "error fetching next item from iterator"
msgstr "当从迭代器中取回下一个成员时出现错误"

#: plpython.c:898
msgid "PL/Python function with return type \"void\" did not return None"
msgstr "返回类型为\"void\"的PL/Python函数不返回None"

#: plpython.c:945
#, c-format
msgid "could not create string representation of Python object in PL/Python function \"%s\" while creating return value"
msgstr "在创建返回值时, 无法计算在PL/Python函数\"%s\"中Python对象的字符串表达式"

#: plpython.c:994
#, c-format
msgid "PL/Python function \"%s\" failed"
msgstr "PL/Python函数 \"%s\" 执行失败"

#: plpython.c:1064
#, c-format
msgid "PyList_SetItem() failed for PL/Python function \"%s\" while setting up arguments"
msgstr "当设置参数的同时, 为PL/Python函数\"%s\"执行PyList_SetItem()时失败"

#: plpython.c:1068
#, c-format
msgid "PyDict_SetItemString() failed for PL/Python function \"%s\" while setting up arguments"
msgstr "当设置参数的同时, 为PL/Python函数\"%s\" 执行PyDict_SetItemString()时失败"

#: plpython.c:1246
msgid "trigger functions can only be called as triggers"
msgstr "触发器函数只能以触发器的形式调用"

#: plpython.c:1250
#, c-format
msgid "PL/Python functions cannot return type %s"
msgstr "PL/Python函数不能返回类型%s"

#: plpython.c:1329
#, c-format
msgid "PL/Python functions cannot accept type %s"
msgstr "PL/Python函数不能接受类型%s"

#: plpython.c:1423
#, c-format
msgid "could not compile PL/Python function \"%s\""
msgstr "无法编译PL/Python函数\"%s\""

#: plpython.c:1735
msgid "could not create new dictionary"
msgstr "无法创建新的字典"

#: plpython.c:1822
#: plpython.c:1911
#: plpython.c:1982
msgid "could not compute string representation of Python object"
msgstr "无法计算Python对象的字符串表达式"

#: plpython.c:1836
#, c-format
msgid "key \"%s\" not found in mapping"
msgstr "在映射中没有找到键\"%s\""

#: plpython.c:1837
msgid "To return null in a column, add the value None to the mapping with the key named after the column."
msgstr "为了在一列中返回空值, 需要在列的后面对带有已命名键的映射添加值None"

#: plpython.c:1881
msgid "length of returned sequence did not match number of columns in row"
msgstr "所返回序列的长度与在记录中列的数量不匹配"

#: plpython.c:1995
#, c-format
msgid "attribute \"%s\" does not exist in Python object"
msgstr "在Python对象中不存在属性\"%s\""

#: plpython.c:1996
msgid "To return null in a column, let the returned object have an attribute named after column with value None."
msgstr "为了在一列中返回空值, 需要让返回的对象在带有值None的列后面的带有已命名属性"

#: plpython.c:2218
msgid "plan.status takes no arguments"
msgstr "plan.status不带有参数"

#: plpython.c:2348
#: plpython.c:2487
msgid "transaction aborted"
msgstr "事务终止"

#: plpython.c:2355
msgid "invalid arguments for plpy.prepare"
msgstr " plpy.prepare的无效参数"

#: plpython.c:2362
msgid "second argument of plpy.prepare must be a sequence"
msgstr "plpy.prepare的第二个参数必须是一个序列"

#: plpython.c:2407
#, c-format
msgid "plpy.prepare: type name at ordinal position %d is not a string"
msgstr "plpy.prepare: 在顺序位置%d的类型名称不是string"

#: plpython.c:2434
msgid "plpy.prepare does not support composite types"
msgstr "plpy.prepare不支持使用组合类型"

#: plpython.c:2462
msgid "unrecognized error in PLy_spi_prepare"
msgstr "在PLy_spi_prepare中无法识别的错误"

#: plpython.c:2464
#: plpython.c:2628
#: plpython.c:2675
#, c-format
msgid "in PL/Python function \"%s\""
msgstr "在PL/Python函数\"%s\"中"

#: plpython.c:2500
msgid "plpy.execute expected a query or a plan"
msgstr "plpy.execute期望一个查询或一个计划"

#: plpython.c:2517
msgid "plpy.execute takes a sequence as its second argument"
msgstr "plpy.execute将一个序列作为它的第二个参数"

#: plpython.c:2533
#: plpython.c:2562
#, c-format
msgid "PL/Python function \"%s\" could not execute plan"
msgstr "PL/Python函数 \"%s\"无法执行计划"

#: plpython.c:2537
#, c-format
msgid "Expected sequence of %d argument, got %d: %s"
msgid_plural "Expected sequence of %d arguments, got %d: %s"
msgstr[0] "期望%d序列参数,但是得到%d: %s"

#: plpython.c:2626
msgid "unrecognized error in PLy_spi_execute_plan"
msgstr "在PLy_spi_execute_plan中出现无法识别的错误"

#: plpython.c:2647
#, c-format
msgid "SPI_execute_plan failed: %s"
msgstr "执行SPI_execute_plan失败: %s"

#: plpython.c:2673
msgid "unrecognized error in PLy_spi_execute_query"
msgstr "在PLy_spi_execute_query中出现无法识别的错误"

#: plpython.c:2684
#, c-format
msgid "SPI_execute failed: %s"
msgstr "SPI_execute执行失败: %s"

#: plpython.c:2744
msgid "unrecognized error in PLy_spi_execute_fetch_result"
msgstr "在PLy_spi_execute_fetch_result中出现无法识别的错误"

#: plpython.c:2780
msgid "untrapped error in initialization"
msgstr "在初始化过程中出现无法捕获的错误"

#: plpython.c:2783
msgid "could not create procedure cache"
msgstr "无法创建存储过程缓存"

#: plpython.c:2795
msgid "could not import \"__main__\" module"
msgstr "无法导入模块\"__main__\" "

#: plpython.c:2802
msgid "could not initialize globals"
msgstr "无法初始化全局变量"

#: plpython.c:2904
msgid "could not parse error message in plpy.elog"
msgstr "无法解析在plpy.elog中的错误消息"

#: plpython.c:3023
#, c-format
msgid "PL/Python: %s"
msgstr "PL/Python: %s"

#: plpython.c:3024
#, c-format
msgid "%s"
msgstr "%s"

#: plpython.c:3114
msgid "out of memory"
msgstr "内存用尽"

